Traceback (most recent call last):
  File "/home/runner/miniconda3/envs/ogzaf-dev/lib/python3.11/site-packages/jupyter_cache/executors/utils.py", line 58, in single_nb_execution
    executenb(
  File "/home/runner/miniconda3/envs/ogzaf-dev/lib/python3.11/site-packages/nbclient/client.py", line 1314, in execute
    return NotebookClient(nb=nb, resources=resources, km=km, **kwargs).execute()
           ^^^^^^^^^^^^^^^^^^^^^^^^^^^^^^^^^^^^^^^^^^^^^^^^^^^^^^^^^^^^^^^^^^^^^
  File "/home/runner/miniconda3/envs/ogzaf-dev/lib/python3.11/site-packages/jupyter_core/utils/__init__.py", line 165, in wrapped
    return loop.run_until_complete(inner)
           ^^^^^^^^^^^^^^^^^^^^^^^^^^^^^^
  File "/home/runner/miniconda3/envs/ogzaf-dev/lib/python3.11/asyncio/base_events.py", line 654, in run_until_complete
    return future.result()
           ^^^^^^^^^^^^^^^
  File "/home/runner/miniconda3/envs/ogzaf-dev/lib/python3.11/site-packages/nbclient/client.py", line 709, in async_execute
    await self.async_execute_cell(
  File "/home/runner/miniconda3/envs/ogzaf-dev/lib/python3.11/site-packages/nbclient/client.py", line 1062, in async_execute_cell
    await self._check_raise_for_error(cell, cell_index, exec_reply)
  File "/home/runner/miniconda3/envs/ogzaf-dev/lib/python3.11/site-packages/nbclient/client.py", line 918, in _check_raise_for_error
    raise CellExecutionError.from_cell_and_msg(cell, exec_reply_content)
nbclient.exceptions.CellExecutionError: An error occurred while executing the following cell:
------------------
import os
import ogcore.demographics as demog
plot_path = os.path.join(os.path.abspath(''), 'images')

fert_rates, fig = demog.get_fert(
    totpers=100,
    min_age=0,
    max_age=99,
    country_id="710",
    start_year=YEAR_TO_PLOT,
    end_year=YEAR_TO_PLOT,
    graph=True,
    plot_path=None,
    download_path=None,
)
plt.savefig(os.path.join(plot_path, "fert_rates.png"), dpi=300)
plt.show()
------------------


[0;31m---------------------------------------------------------------------------[0m
[0;31mNameError[0m                                 Traceback (most recent call last)
Cell [0;32mIn[1], line 10[0m
[1;32m      2[0m [38;5;28;01mimport[39;00m [38;5;21;01mogcore[39;00m[38;5;21;01m.[39;00m[38;5;21;01mdemographics[39;00m [38;5;28;01mas[39;00m [38;5;21;01mdemog[39;00m
[1;32m      3[0m plot_path [38;5;241m=[39m os[38;5;241m.[39mpath[38;5;241m.[39mjoin(os[38;5;241m.[39mpath[38;5;241m.[39mabspath([38;5;124m'[39m[38;5;124m'[39m), [38;5;124m'[39m[38;5;124mimages[39m[38;5;124m'[39m)
[1;32m      5[0m fert_rates, fig [38;5;241m=[39m demog[38;5;241m.[39mget_fert(
[1;32m      6[0m     totpers[38;5;241m=[39m[38;5;241m100[39m,
[1;32m      7[0m     min_age[38;5;241m=[39m[38;5;241m0[39m,
[1;32m      8[0m     max_age[38;5;241m=[39m[38;5;241m99[39m,
[1;32m      9[0m     country_id[38;5;241m=[39m[38;5;124m"[39m[38;5;124m710[39m[38;5;124m"[39m,
[0;32m---> 10[0m     start_year[38;5;241m=[39m[43mYEAR_TO_PLOT[49m,
[1;32m     11[0m     end_year[38;5;241m=[39mYEAR_TO_PLOT,
[1;32m     12[0m     graph[38;5;241m=[39m[38;5;28;01mTrue[39;00m,
[1;32m     13[0m     plot_path[38;5;241m=[39m[38;5;28;01mNone[39;00m,
[1;32m     14[0m     download_path[38;5;241m=[39m[38;5;28;01mNone[39;00m,
[1;32m     15[0m )
[1;32m     16[0m plt[38;5;241m.[39msavefig(os[38;5;241m.[39mpath[38;5;241m.[39mjoin(plot_path, [38;5;124m"[39m[38;5;124mfert_rates.png[39m[38;5;124m"[39m), dpi[38;5;241m=[39m[38;5;241m300[39m)
[1;32m     17[0m plt[38;5;241m.[39mshow()

[0;31mNameError[0m: name 'YEAR_TO_PLOT' is not defined

